Workbook

Sheet BAOCAOKD.TBLDMKHACHHANG
A1: KHACHHANGID | B1: TENKHACHHANG | C1: DIACHI | D1: DIENTHOAI | E1: THONGTINKHAC | F1: THEODOI | G1: THOIGIANCAPNHAT | H1: NGUOICAPNHATID | I1: LOAI | J1: DKKD | K1: GHICHU | L1: NGUOICAPNHATIDMaping
A2: 585 | B2: ABB LTD | F2: 1 | G2: 2021-04-23 10:08:46 | H2: 1548 | L2: =IFERROR(VLOOKUP(H2,users!$A$2:$D$205,2,FALSE),"716336b8-0698-49d0-a65c-b5f45d724290") -> 716336b8-0698-49d0-a65c-b5f45d724198
A3: 586 | B3: BQL bảo trì phần mềm và Tuxedo | F3: 1 | G3: 2021-04-23 10:08:46 | H3: 1548 | L3: =IFERROR(VLOOKUP(H3,users!$A$2:$D$205,2,FALSE),"716336b8-0698-49d0-a65c-b5f45d724290") -> 716336b8-0698-49d0-a65c-b5f45d724198
A4: 587 | B4: Báo Hải Quan | F4: 1 | G4: 2021-04-23 10:08:46 | H4: 1548 | L4: =IFERROR(VLOOKUP(H4,users!$A$2:$D$205,2,FALSE),"716336b8-0698-49d0-a65c-b5f45d724290") -> 716336b8-0698-49d0-a65c-b5f45d724198
A5: 588 | B5: Bệnh viện Hữu nghị Việt Đức | F5: 1 | G5: 2021-04-23 10:07:50 | H5: 1548 | L5: =IFERROR(VLOOKUP(H5,users!$A$2:$D$205,2,FALSE),"716336b8-0698-49d0-a65c-b5f45d724290") -> 716336b8-0698-49d0-a65c-b5f45d724198
A6: 589 | B6: Bệnh viện Nhi Trung Ương | F6: 1 | G6: 2021-04-23 09:47:54 | H6: 1548 | L6: =IFERROR(VLOOKUP(H6,users!$A$2:$D$205,2,FALSE),"716336b8-0698-49d0-a65c-b5f45d724290") -> 716336b8-0698-49d0-a65c-b5f45d724198
A7: 591 | B7: Bệnh viện Phổi Trung Ương - Quỹ toàn cầu phòng chống lao GĐ 2018-2020 | F7: 1 | G7: 2021-04-23 10:09:13 | H7: 1548 | L7: =IFERROR(VLOOKUP(H7,users!$A$2:$D$205,2,FALSE),"716336b8-0698-49d0-a65c-b5f45d724290") -> 716336b8-0698-49d0-a65c-b5f45d724198
A8: 592 | B8: Bộ Tư lệnh 86/BQP | F8: 1 | G8: 2021-04-23 10:08:46 | H8: 1548 | L8: =IFERROR(VLOOKUP(H8,users!$A$2:$D$205,2,FALSE),"716336b8-0698-49d0-a65c-b5f45d724290") -> 716336b8-0698-49d0-a65c-b5f45d724198
A9: 593 | B9: BQL DA Trường Đại học Việt Đức | F9: 1 | G9: 2021-04-23 10:08:46 | H9: 1548 | L9: =IFERROR(VLOOKUP(H9,users!$A$2:$D$205,2,FALSE),"716336b8-0698-49d0-a65c-b5f45d724290") -> 716336b8-0698-49d0-a65c-b5f45d724198
A10: 594 | B10: CN Công ty cổ phần Diana Unicharm - Bắc Ninh | F10: 1 | G10: 2021-04-23 10:14:08 | H10: 1548 | L10: =IFERROR(VLOOKUP(H10,users!$A$2:$D$205,2,FALSE),"716336b8-0698-49d0-a65c-b5f45d724290") -> 716336b8-0698-49d0-a65c-b5f45d724198
A11: 595 | B11: CN Trung tâm CNTT Tập đoàn Bảo Việt | F11: 1 | G11: 2021-04-23 10:12:31 | H11: 1548 | L11: =IFERROR(VLOOKUP(H11,users!$A$2:$D$205,2,FALSE),"716336b8-0698-49d0-a65c-b5f45d724290") -> 716336b8-0698-49d0-a65c-b5f45d724198
A12: 596 | B12: CN Công ty cổ phần Giao nhận và vận chuyển Indo Trần | F12: 1 | G12: 2021-04-23 02:10:35 | H12: 1548 | L12: =IFERROR(VLOOKUP(H12,users!$A$2:$D$205,2,FALSE),"716336b8-0698-49d0-a65c-b5f45d724290") -> 716336b8-0698-49d0-a65c-b5f45d724198
A13: 597 | B13: CN TCT Điện lực TP HCM TNHH - Công ty CNTT Điện lực TP HCM | F13: 1 | G13: 2021-04-23 10:13:00 | H13: 1548 | L13: =IFERROR(VLOOKUP(H13,users!$A$2:$D$205,2,FALSE),"716336b8-0698-49d0-a65c-b5f45d724290") -> 716336b8-0698-49d0-a65c-b5f45d724198
... A104: 726 | B104: Ngân hàng TMCP Công thương Việt Nam (VietinBank) | F104: 1 | G104: 2021-04-23 02:56:26 | H104: 1548 | L104: =IFERROR(VLOOKUP(H104,users!$A$2:$D$205,2,FALSE),"716336b8-0698-49d0-a65c-b5f45d724290") -> 716336b8-0698-49d0-a65c-b5f45d724198
A105: 788 | B105: Khachhang-Dum-01 | C105: 152 Thuy Khue, Tay Ho, Ha Noi | F105: 1 | G105: 2021-04-28 02:33:49 | H105: 1605 | L105: =IFERROR(VLOOKUP(H105,users!$A$2:$D$205,2,FALSE),"716336b8-0698-49d0-a65c-b5f45d724290") -> 716336b8-0698-49d0-a65c-b5f45d724290
A106: 728 | B106: Ngân hàng TMCP Đông Nam Á (SeABank) | F106: 1 | G106: 2021-04-23 04:34:12 | H106: 1548 | L106: =IFERROR(VLOOKUP(H106,users!$A$2:$D$205,2,FALSE),"716336b8-0698-49d0-a65c-b5f45d724290") -> 716336b8-0698-49d0-a65c-b5f45d724198
A107: 729 | B107: Ngân hàng TMCP Kiên Long (KienLong Bank) | F107: 1 | G107: 2021-04-23 02:57:19 | H107: 1548 | L107: =IFERROR(VLOOKUP(H107,users!$A$2:$D$205,2,FALSE),"716336b8-0698-49d0-a65c-b5f45d724290") -> 716336b8-0698-49d0-a65c-b5f45d724198
A108: 730 | B108: Ngân hàng TMCP Kỹ thương Việt Nam (Techcombank) | F108: 1 | G108: 2021-04-23 02:57:45 | H108: 1548 | L108: =IFERROR(VLOOKUP(H108,users!$A$2:$D$205,2,FALSE),"716336b8-0698-49d0-a65c-b5f45d724290") -> 716336b8-0698-49d0-a65c-b5f45d724198
A109: 731 | B109: Ngân hàng TMCP Ngoại thương Việt Nam (Vietcombank) | F109: 1 | G109: 2021-04-23 02:58:05 | H109: 1548 | L109: =IFERROR(VLOOKUP(H109,users!$A$2:$D$205,2,FALSE),"716336b8-0698-49d0-a65c-b5f45d724290") -> 716336b8-0698-49d0-a65c-b5f45d724198
A110: 732 | B110: Ngân hàng TMCP Phương Đông (OCB) | F110: 1 | G110: 2021-04-23 04:24:17 | H110: 1548 | L110: =IFERROR(VLOOKUP(H110,users!$A$2:$D$205,2,FALSE),"716336b8-0698-49d0-a65c-b5f45d724290") -> 716336b8-0698-49d0-a65c-b5f45d724198
A111: 733 | B111: Ngân hàng TMCP Quốc dân (NCB) | F111: 1 | G111: 2021-04-23 10:08:46 | H111: 1548 | L111: =IFERROR(VLOOKUP(H111,users!$A$2:$D$205,2,FALSE),"716336b8-0698-49d0-a65c-b5f45d724290") -> 716336b8-0698-49d0-a65c-b5f45d724198
A112: 734 | B112: Ngân hàng TMCP Quốc Tế Việt Nam (VIB) | F112: 1 | G112: 2021-04-23 10:08:46 | H112: 1548 | L112: =IFERROR(VLOOKUP(H112,users!$A$2:$D$205,2,FALSE),"716336b8-0698-49d0-a65c-b5f45d724290") -> 716336b8-0698-49d0-a65c-b5f45d724198
A113: 735 | B113: Ngân hàng TMCP Sài Gòn - Hà Nội (SHB) | F113: 1 | G113: 2021-04-23 04:25:31 | H113: 1548 | L113: =IFERROR(VLOOKUP(H113,users!$A$2:$D$205,2,FALSE),"716336b8-0698-49d0-a65c-b5f45d724290") -> 716336b8-0698-49d0-a65c-b5f45d724198
A114: 736 | B114: Ngân hàng TMCP Sài Gòn công thương (Saigonbank) | F114: 1 | G114: 2021-04-23 04:27:39 | H114: 1548 | L114: =IFERROR(VLOOKUP(H114,users!$A$2:$D$205,2,FALSE),"716336b8-0698-49d0-a65c-b5f45d724290") -> 716336b8-0698-49d0-a65c-b5f45d724198
A115: 737 | B115: Ngân hàng TMCP Sài Gòn Thương Tín (Sacombank) | F115: 1 | G115: 2021-04-23 04:28:03 | H115: 1548 | L115: =IFERROR(VLOOKUP(H115,users!$A$2:$D$205,2,FALSE),"716336b8-0698-49d0-a65c-b5f45d724290") -> 716336b8-0698-49d0-a65c-b5f45d724198
A116: 790 | B116: Công ty cổ phần Văn phòng phẩm Hồng Hà | F116: 1 | G116: 2021-05-03 08:09:35 | H116: 1548 | L116: =IFERROR(VLOOKUP(H116,users!$A$2:$D$205,2,FALSE),"716336b8-0698-49d0-a65c-b5f45d724290") -> 716336b8-0698-49d0-a65c-b5f45d724198
A117: 739 | B117: Ngân hàng TMCP Việt Nam Thịnh Vượng (VPBank) | F117: 1 | G117: 2021-04-23 04:28:50 | H117: 1548 | L117: =IFERROR(VLOOKUP(H117,users!$A$2:$D$205,2,FALSE),"716336b8-0698-49d0-a65c-b5f45d724290") -> 716336b8-0698-49d0-a65c-b5f45d724198
... A140: 762 | B140: Tổng công ty Hóa dầu Petrolimex - CTCP (PLC) | F140: 1 | G140: 2021-04-24 05:34:09 | H140: 1548 | L140: =IFERROR(VLOOKUP(H140,users!$A$2:$D$205,2,FALSE),"716336b8-0698-49d0-a65c-b5f45d724290") -> 716336b8-0698-49d0-a65c-b5f45d724198
A141: 763 | B141: Tổng công ty Khí Việt Nam - CTCP (PV GAS) | C141: Tầng 12, 12A, 14 và tầng 15, Tòa nhà PV GAS, số 673 đường Nguyễn Hữu Thọ, xã Phước Kiển, huyện Nhà Bè, TP.HCM | D141: +84.28. 3781 6777 Fax: +84.28. 3781 5666 | F141: 1 | G141: 2021-04-24 05:38:42 | H141: 1548 | L141: =IFERROR(VLOOKUP(H141,users!$A$2:$D$205,2,FALSE),"716336b8-0698-49d0-a65c-b5f45d724290") -> 716336b8-0698-49d0-a65c-b5f45d724198
A142: 764 | B142: Tổng công ty Viglacera - CTCP | F142: 1 | G142: 2021-04-24 05:34:54 | H142: 1548 | L142: =IFERROR(VLOOKUP(H142,users!$A$2:$D$205,2,FALSE),"716336b8-0698-49d0-a65c-b5f45d724290") -> 716336b8-0698-49d0-a65c-b5f45d724198
A143: 765 | B143: Trung tâm Chính phủ điện tử | F143: 1 | G143: 2021-04-24 05:25:30 | H143: 1548 | L143: =IFERROR(VLOOKUP(H143,users!$A$2:$D$205,2,FALSE),"716336b8-0698-49d0-a65c-b5f45d724290") -> 716336b8-0698-49d0-a65c-b5f45d724198
A144: 766 | B144: Trung tâm Internet Việt Nam (VNNIC) | F144: 1 | G144: 2021-04-23 08:58:14 | H144: 1577 | L144: =IFERROR(VLOOKUP(H144,users!$A$2:$D$205,2,FALSE),"716336b8-0698-49d0-a65c-b5f45d724290") -> 716336b8-0698-49d0-a65c-b5f45d724099
A145: 767 | B145: Trung tâm Lưu ký chứng khoán Việt Nam (VSD) | F145: 1 | G145: 2021-04-24 05:26:07 | H145: 1548 | L145: =IFERROR(VLOOKUP(H145,users!$A$2:$D$205,2,FALSE),"716336b8-0698-49d0-a65c-b5f45d724290") -> 716336b8-0698-49d0-a65c-b5f45d724198
A146: 792 | B146: Công ty Tài chính TNHH MTV Lotte Việt Nam (Lotte Finance Vietnam) | F146: 1 | G146: 2021-05-04 12:53:36 | H146: 1548 | L146: =IFERROR(VLOOKUP(H146,users!$A$2:$D$205,2,FALSE),"716336b8-0698-49d0-a65c-b5f45d724290") -> 716336b8-0698-49d0-a65c-b5f45d724198
A147: 769 | B147: Trung tâm Thông tin và Dự báo kinh tế - xã hội Quốc gia (NCIF) | F147: 1 | G147: 2021-04-24 05:24:17 | H147: 1548 | L147: =IFERROR(VLOOKUP(H147,users!$A$2:$D$205,2,FALSE),"716336b8-0698-49d0-a65c-b5f45d724290") -> 716336b8-0698-49d0-a65c-b5f45d724198
A148: 770 | B148: Trung tâm Tin học - Kiểm toán Nhà nước (KTNN) | F148: 1 | G148: 2021-04-24 05:32:07 | H148: 1548 | L148: =IFERROR(VLOOKUP(H148,users!$A$2:$D$205,2,FALSE),"716336b8-0698-49d0-a65c-b5f45d724290") -> 716336b8-0698-49d0-a65c-b5f45d724198
A149: 771 | B149: Trung tâm Tin học và công nghệ truyền hình (VTV) | F149: 1 | G149: 2021-05-28 09:48:44 | H149: 1548 | L149: =IFERROR(VLOOKUP(H149,users!$A$2:$D$205,2,FALSE),"716336b8-0698-49d0-a65c-b5f45d724290") -> 716336b8-0698-49d0-a65c-b5f45d724198
A150: 772 | B150: Trung tâm Ứng dụng và phát triển công nghệ địa chính | F150: 1 | G150: 2021-04-24 05:32:38 | H150: 1548 | L150: =IFERROR(VLOOKUP(H150,users!$A$2:$D$205,2,FALSE),"716336b8-0698-49d0-a65c-b5f45d724290") -> 716336b8-0698-49d0-a65c-b5f45d724198
A151: 773 | B151: Trường Đại học Bách Khoa | F151: 1 | G151: 2021-04-23 10:08:46 | H151: 1548 | L151: =IFERROR(VLOOKUP(H151,users!$A$2:$D$205,2,FALSE),"716336b8-0698-49d0-a65c-b5f45d724290") -> 716336b8-0698-49d0-a65c-b5f45d724198
A152: 774 | B152: Trường Đại học Luật TP HCM | F152: 1 | G152: 2021-04-23 10:08:46 | H152: 1548 | L152: =IFERROR(VLOOKUP(H152,users!$A$2:$D$205,2,FALSE),"716336b8-0698-49d0-a65c-b5f45d724290") -> 716336b8-0698-49d0-a65c-b5f45d724198
...

Sheet users
A1: ID | B1: ID Map | C1: Họ Và Tên
A2: 1577 | B2: 716336b8-0698-49d0-a65c-b5f45d724099 | C2: Nguyễn Minh Đức
A3: 1593 | B3: 716336b8-0698-49d0-a65c-b5f45d724100 | C3: Lê Thị Thảo
A4: 1658 | B4: 716336b8-0698-49d0-a65c-b5f45d724101 | C4: Quách Ngọc Phú
A5: 1660 | B5: 716336b8-0698-49d0-a65c-b5f45d724102 | C5: Nguyễn Thị Oanh
A6: 1663 | B6: 716336b8-0698-49d0-a65c-b5f45d724103 | C6: Nguyễn Phương Dung
A7: 1665 | B7: 716336b8-0698-49d0-a65c-b5f45d724104 | C7: Nguyễn Văn Quý
A8: 1666 | B8: 716336b8-0698-49d0-a65c-b5f45d724105 | C8: Vũ Đức Chính
A9: 1668 | B9: 716336b8-0698-49d0-a65c-b5f45d724106 | C9: Nguyễn Ngọc Quang
A10: 1671 | B10: 716336b8-0698-49d0-a65c-b5f45d724107 | C10: Phạm Gia Anh Thư
A11: 1673 | B11: 716336b8-0698-49d0-a65c-b5f45d724108 | C11: Nguyễn Kiêm Thắng
A12: 1675 | B12: 716336b8-0698-49d0-a65c-b5f45d724109 | C12: Trần Hữu Tuệ
A13: 1678 | B13: 716336b8-0698-49d0-a65c-b5f45d724110 | C13: Nguyễn Thế Giáp
... A205: 2011 | B205: 716336b8-0698-49d0-a65c-b5f45d724302 | C205: Vũ Linh Chi
